Workbook

Sheet LEIA-ME
A1: Dashboard Administrativo | Projeto de Portfólio
A3: PROJETO SIMULADO PARA PORTFÓLIO — os dados abaixo são fictícios e servem para demonstrar competências em Excel e Power BI.
A5: Objetivo | B5: Criar um controle de solicitações administrativas e acompanhar volume, prazos, prioridades e desempenho por meio de indicadores.
A6: Ferramentas | B6: Excel + Power BI
A7: Base criada | B7: 60 solicitações administrativas simuladas
A8: Período | B8: Janeiro a junho de 2026
A9: Indicadores | B9: Total, concluídas, em andamento, pendentes, atrasadas, taxa de conclusão e tempo médio de conclusão
A10: Análises | B10: Por setor, tipo de demanda, prioridade, status e mês
A11: Status do projeto | B11: Base e dashboard em Excel concluídos; arquivo preparado para importação no Power BI.
A12: Observação | B12: Não representa experiência profissional em uma empresa específica. É um projeto demonstrativo para portfólio.

Sheet Listas
A1: Setores | B1: Tipos de Demanda | C1: Responsáveis | D1: Prioridades | E1: Status
A2: Financeiro | B2: Compra de material | C2: Ana Lima | D2: Baixa | E2: Concluída
A3: RH | B3: Atualização cadastral | C3: Bruno Souza | D3: Média | E3: Em andamento
A4: Comercial | B4: Emissão de documento | C4: Carla Mendes | D4: Alta | E4: Pendente
A5: Operações | B5: Organização de arquivo | C5: Diego Alves
A6: TI | B6: Apoio a reunião | C6: Elisa Rocha
A7: Diretoria | B7: Cadastro em sistema
B8: Relatório administrativo
B9: Solicitação de pagamento

Sheet Base Administrativa
A1: Base de Solicitações Administrativas — 2026
O2: Data de referência | P2: 46203
A3: Protocolo | B3: Data Abertura | C3: Setor Solicitante | D3: Tipo de Demanda | E3: Responsável | F3: Prioridade | G3: Prazo | H3: Status | I3: Data Conclusão | J3: Dias p/ Conclusão | K3: Atrasada? | L3: Mês | M3: Observação
A4: ADM-001 | B4: 46078 | C4: Diretoria | D4: Organização de arquivo | E4: Diego Alves | F4: Média | G4: 46085 | H4: Concluída | I4: 46086 | J4: =IF(I4="","",I4-B4) -> 8 | K4: =IF(H4="Concluída",IF(I4>G4,"Sim","Não"),IF($P$2>G4,"Sim","Não")) -> Sim | L4: =TEXT(B4,"mmm") -> fev | M4: Demanda simulada para portfólio
A5: ADM-002 | B5: 46037 | C5: Diretoria | D5: Emissão de documento | E5: Diego Alves | F5: Alta | G5: 46041 | H5: Pendente | J5: =IF(I5="","",I5-B5) | K5: =IF(H5="Concluída",IF(I5>G5,"Sim","Não"),IF($P$2>G5,"Sim","Não")) -> Sim | L5: =TEXT(B5,"mmm") -> jan | M5: Demanda simulada para portfólio
A6: ADM-003 | B6: 46131 | C6: Diretoria | D6: Organização de arquivo | E6: Ana Lima | F6: Média | G6: 46138 | H6: Em andamento | J6: =IF(I6="","",I6-B6) | K6: =IF(H6="Concluída",IF(I6>G6,"Sim","Não"),IF($P$2>G6,"Sim","Não")) -> Sim | L6: =TEXT(B6,"mmm") -> abr | M6: Demanda simulada para portfólio
A7: ADM-004 | B7: 46063 | C7: RH | D7: Organização de arquivo | E7: Elisa Rocha | F7: Média | G7: 46070 | H7: Em andamento | J7: =IF(I7="","",I7-B7) | K7: =IF(H7="Concluída",IF(I7>G7,"Sim","Não"),IF($P$2>G7,"Sim","Não")) -> Sim | L7: =TEXT(B7,"mmm") -> fev | M7: Demanda simulada para portfólio
A8: ADM-005 | B8: 46126 | C8: Comercial | D8: Organização de arquivo | E8: Elisa Rocha | F8: Baixa | G8: 46138 | H8: Pendente | J8: =IF(I8="","",I8-B8) | K8: =IF(H8="Concluída",IF(I8>G8,"Sim","Não"),IF($P$2>G8,"Sim","Não")) -> Sim | L8: =TEXT(B8,"mmm") -> abr | M8: Demanda simulada para portfólio
A9: ADM-006 | B9: 46102 | C9: TI | D9: Atualização cadastral | E9: Elisa Rocha | F9: Baixa | G9: 46114 | H9: Concluída | I9: 46112 | J9: =IF(I9="","",I9-B9) -> 10 | K9: =IF(H9="Concluída",IF(I9>G9,"Sim","Não"),IF($P$2>G9,"Sim","Não")) -> Não | L9: =TEXT(B9,"mmm") -> mar | M9: Demanda simulada para portfólio
A10: ADM-007 | B10: 46195 | C10: TI | D10: Cadastro em sistema | E10: Carla Mendes | F10: Alta | G10: 46199 | H10: Concluída | I10: 46202 | J10: =IF(I10="","",I10-B10) -> 7 | K10: =IF(H10="Concluída",IF(I10>G10,"Sim","Não"),IF($P$2>G10,"Sim","Não")) -> Sim | L10: =TEXT(B10,"mmm") -> jun | M10: Demanda simulada para portfólio
A11: ADM-008 | B11: 46078 | C11: Financeiro | D11: Apoio a reunião | E11: Bruno Souza | F11: Alta | G11: 46082 | H11: Concluída | I11: 46082 | J11: =IF(I11="","",I11-B11) -> 4 | K11: =IF(H11="Concluída",IF(I11>G11,"Sim","Não"),IF($P$2>G11,"Sim","Não")) -> Não | L11: =TEXT(B11,"mmm") -> fev | M11: Demanda simulada para portfólio
A12: ADM-009 | B12: 46182 | C12: TI | D12: Emissão de documento | E12: Ana Lima | F12: Baixa | G12: 46194 | H12: Concluída | I12: 46191 | J12: =IF(I12="","",I12-B12) -> 9 | K12: =IF(H12="Concluída",IF(I12>G12,"Sim","Não"),IF($P$2>G12,"Sim","Não")) -> Não | L12: =TEXT(B12,"mmm") -> jun | M12: Demanda simulada para portfólio
A13: ADM-010 | B13: 46038 | C13: Financeiro | D13: Relatório administrativo | E13: Bruno Souza | F13: Média | G13: 46045 | H13: Em andamento | J13: =IF(I13="","",I13-B13) | K13: =IF(H13="Concluída",IF(I13>G13,"Sim","Não"),IF($P$2>G13,"Sim","Não")) -> Sim | L13: =TEXT(B13,"mmm") -> jan | M13: Demanda simulada para portfólio
A14: ADM-011 | B14: 46050 | C14: TI | D14: Cadastro em sistema | E14: Ana Lima | F14: Média | G14: 46057 | H14: Concluída | I14: 46057 | J14: =IF(I14="","",I14-B14) -> 7 | K14: =IF(H14="Concluída",IF(I14>G14,"Sim","Não"),IF($P$2>G14,"Sim","Não")) -> Não | L14: =TEXT(B14,"mmm") -> jan | M14: Demanda simulada para portfólio
A15: ADM-012 | B15: 46144 | C15: TI | D15: Atualização cadastral | E15: Ana Lima | F15: Média | G15: 46151 | H15: Concluída | I15: 46146 | J15: =IF(I15="","",I15-B15) -> 2 | K15: =IF(H15="Concluída",IF(I15>G15,"Sim","Não"),IF($P$2>G15,"Sim","Não")) -> Não | L15: =TEXT(B15,"mmm") -> mai | M15: Demanda simulada para portfólio
A16: ADM-013 | B16: 46061 | C16: Diretoria | D16: Apoio a reunião | E16: Carla Mendes | F16: Alta | G16: 46065 | H16: Em andamento | J16: =IF(I16="","",I16-B16) | K16: =IF(H16="Concluída",IF(I16>G16,"Sim","Não"),IF($P$2>G16,"Sim","Não")) -> Sim | L16: =TEXT(B16,"mmm") -> fev | M16: Demanda simulada para portfólio
A17: ADM-014 | B17: 46181 | C17: Diretoria | D17: Relatório administrativo | E17: Carla Mendes | F17: Média | G17: 46188 | H17: Concluída | I17: 46182 | J17: =IF(I17="","",I17-B17) -> 1 | K17: =IF(H17="Concluída",IF(I17>G17,"Sim","Não"),IF($P$2>G17,"Sim","Não")) -> Não | L17: =TEXT(B17,"mmm") -> jun | M17: Demanda simulada para portfólio
A18: ADM-015 | B18: 46038 | C18: RH | D18: Compra de material | E18: Elisa Rocha | F18: Baixa | G18: 46050 | H18: Pendente | J18: =IF(I18="","",I18-B18) | K18: =IF(H18="Concluída",IF(I18>G18,"Sim","Não"),IF($P$2>G18,"Sim","Não")) -> Sim | L18: =TEXT(B18,"mmm") -> jan | M18: Demanda simulada para portfólio
A19: ADM-016 | B19: 46148 | C19: Financeiro | D19: Emissão de documento | E19: Elisa Rocha | F19: Baixa | G19: 46160 | H19: Concluída | I19: 46155 | J19: =IF(I19="","",I19-B19) -> 7 | K19: =IF(H19="Concluída",IF(I19>G19,"Sim","Não"),IF($P$2>G19,"Sim","Não")) -> Não | L19: =TEXT(B19,"mmm") -> mai | M19: Demanda simulada para portfólio
A20: ADM-017 | B20: 46039 | C20: Comercial | D20: Relatório administrativo | E20: Bruno Souza | F20: Baixa | G20: 46051 | H20: Concluída | I20: 46041 | J20: =IF(I20="","",I20-B20) -> 2 | K20: =IF(H20="Concluída",IF(I20>G20,"Sim","Não"),IF($P$2>G20,"Sim","Não")) -> Não | L20: =TEXT(B20,"mmm") -> jan | M20: Demanda simulada para portfólio
A21: ADM-018 | B21: 46044 | C21: TI | D21: Compra de material | E21: Ana Lima | F21: Alta | G21: 46048 | H21: Pendente | J21: =IF(I21="","",I21-B21) | K21: =IF(H21="Concluída",IF(I21>G21,"Sim","Não"),IF($P$2>G21,"Sim","Não")) -> Sim | L21: =TEXT(B21,"mmm") -> jan | M21: Demanda simulada para portfólio
A22: ADM-019 | B22: 46166 | C22: Financeiro | D22: Apoio a reunião | E22: Diego Alves | F22: Alta | G22: 46170 | H22: Concluída | I22: 46172 | J22: =IF(I22="","",I22-B22) -> 6 | K22: =IF(H22="Concluída",IF(I22>G22,"Sim","Não"),IF($P$2>G22,"Sim","Não")) -> Sim | L22: =TEXT(B22,"mmm") -> mai | M22: Demanda simulada para portfólio
A23: ADM-020 | B23: 46167 | C23: Diretoria | D23: Relatório administrativo | E23: Ana Lima | F23: Baixa | G23: 46179 | H23: Pendente | J23: =IF(I23="","",I23-B23) | K23: =IF(H23="Concluída",IF(I23>G23,"Sim","Não"),IF($P$2>G23,"Sim","Não")) -> Sim | L23: =TEXT(B23,"mmm") -> mai | M23: Demanda simulada para portfólio
A24: ADM-021 | B24: 46139 | C24: RH | D24: Apoio a reunião | E24: Bruno Souza | F24: Baixa | G24: 46151 | H24: Concluída | I24: 46146 | J24: =IF(I24="","",I24-B24) -> 7 | K24: =IF(H24="Concluída",IF(I24>G24,"Sim","Não"),IF($P$2>G24,"Sim","Não")) -> Não | L24: =TEXT(B24,"mmm") -> abr | M24: Demanda simulada para portfólio
A25: ADM-022 | B25: 46129 | C25: TI | D25: Cadastro em sistema | E25: Ana Lima | F25: Média | G25: 46136 | H25: Concluída | I25: 46132 | J25: =IF(I25="","",I25-B25) -> 3 | K25: =IF(H25="Concluída",IF(I25>G25,"Sim","Não"),IF($P$2>G25,"Sim","Não")) -> Não | L25: =TEXT(B25,"mmm") -> abr | M25: Demanda simulada para portfólio
A26: ADM-023 | B26: 46038 | C26: Financeiro | D26: Emissão de documento | E26: Diego Alves | F26: Baixa | G26: 46050 | H26: Concluída | I26: 46043 | J26: =IF(I26="","",I26-B26) -> 5 | K26: =IF(H26="Concluída",IF(I26>G26,"Sim","Não"),IF($P$2>G26,"Sim","Não")) -> Não | L26: =TEXT(B26,"mmm") -> jan | M26: Demanda simulada para portfólio
A27: ADM-024 | B27: 46109 | C27: Operações | D27: Solicitação de pagamento | E27: Bruno Souza | F27: Média | G27: 46116 | H27: Concluída | I27: 46118 | J27: =IF(I27="","",I27-B27) -> 9 | K27: =IF(H27="Concluída",IF(I27>G27,"Sim","Não"),IF($P$2>G27,"Sim","Não")) -> Sim | L27: =TEXT(B27,"mmm") -> mar | M27: Demanda simulada para portfólio
A28: ADM-025 | B28: 46052 | C28: Financeiro | D28: Compra de material | E28: Bruno Souza | F28: Baixa | G28: 46064 | H28: Concluída | I28: 46061 | J28: =IF(I28="","",I28-B28) -> 9 | K28: =IF(H28="Concluída",IF(I28>G28,"Sim","Não"),IF($P$2>G28,"Sim","Não")) -> Não | L28: =TEXT(B28,"mmm") -> jan | M28: Demanda simulada para portfólio
A29: ADM-026 | B29: 46061 | C29: Financeiro | D29: Emissão de documento | E29: Bruno Souza | F29: Alta | G29: 46065 | H29: Pendente | J29: =IF(I29="","",I29-B29) | K29: =IF(H29="Concluída",IF(I29>G29,"Sim","Não"),IF($P$2>G29,"Sim","Não")) -> Sim | L29: =TEXT(B29,"mmm") -> fev | M29: Demanda simulada para portfólio
A30: ADM-027 | B30: 46040 | C30: Operações | D30: Solicitação de pagamento | E30: Elisa Rocha | F30: Baixa | G30: 46052 | H30: Em andamento | J30: =IF(I30="","",I30-B30) | K30: =IF(H30="Concluída",IF(I30>G30,"Sim","Não"),IF($P$2>G30,"Sim","Não")) -> Sim | L30: =TEXT(B30,"mmm") -> jan | M30: Demanda simulada para portfólio
A31: ADM-028 | B31: 46079 | C31: Comercial | D31: Emissão de documento | E31: Bruno Souza | F31: Baixa | G31: 46091 | H31: Concluída | I31: 46084 | J31: =IF(I31="","",I31-B31) -> 5 | K31: =IF(H31="Concluída",IF(I31>G31,"Sim","Não"),IF($P$2>G31,"Sim","Não")) -> Não | L31: =TEXT(B31,"mmm") -> fev | M31: Demanda simulada para portfólio
A32: ADM-029 | B32: 46133 | C32: RH | D32: Solicitação de pagamento | E32: Elisa Rocha | F32: Média | G32: 46140 | H32: Concluída | I32: 46138 | J32: =IF(I32="","",I32-B32) -> 5 | K32: =IF(H32="Concluída",IF(I32>G32,"Sim","Não"),IF($P$2>G32,"Sim","Não")) -> Não | L32: =TEXT(B32,"mmm") -> abr | M32: Demanda simulada para portfólio
A33: ADM-030 | B33: 46097 | C33: Diretoria | D33: Apoio a reunião | E33: Elisa Rocha | F33: Alta | G33: 46101 | H33: Em andamento | J33: =IF(I33="","",I33-B33) | K33: =IF(H33="Concluída",IF(I33>G33,"Sim","Não"),IF($P$2>G33,"Sim","Não")) -> Sim | L33: =TEXT(B33,"mmm") -> mar | M33: Demanda simulada para portfólio
A34: ADM-031 | B34: 46094 | C34: Operações | D34: Compra de material | E34: Ana Lima | F34: Alta | G34: 46098 | H34: Em andamento | J34: =IF(I34="","",I34-B34) | K34: =IF(H34="Concluída",IF(I34>G34,"Sim","Não"),IF($P$2>G34,"Sim","Não")) -> Sim | L34: =TEXT(B34,"mmm") -> mar | M34: Demanda simulada para portfólio
A35: ADM-032 | B35: 46074 | C35: TI | D35: Apoio a reunião | E35: Bruno Souza | F35: Alta | G35: 46078 | H35: Concluída | I35: 46079 | J35: =IF(I35="","",I35-B35) -> 5 | K35: =IF(H35="Concluída",IF(I35>G35,"Sim","Não"),IF($P$2>G35,"Sim","Não")) -> Sim | L35: =TEXT(B35,"mmm") -> fev | M35: Demanda simulada para portfólio
A36: ADM-033 | B36: 46134 | C36: Diretoria | D36: Compra de material | E36: Elisa Rocha | F36: Média | G36: 46141 | H36: Em andamento | J36: =IF(I36="","",I36-B36) | K36: =IF(H36="Concluída",IF(I36>G36,"Sim","Não"),IF($P$2>G36,"Sim","Não")) -> Sim | L36: =TEXT(B36,"mmm") -> abr | M36: Demanda simulada para portfólio
A37: ADM-034 | B37: 46146 | C37: Comercial | D37: Atualização cadastral | E37: Ana Lima | F37: Média | G37: 46153 | H37: Concluída | I37: 46147 | J37: =IF(I37="","",I37-B37) -> 1 | K37: =IF(H37="Concluída",IF(I37>G37,"Sim","Não"),IF($P$2>G37,"Sim","Não")) -> Não | L37: =TEXT(B37,"mmm") -> mai | M37: Demanda simulada para portfólio
A38: ADM-035 | B38: 46042 | C38: Diretoria | D38: Atualização cadastral | E38: Bruno Souza | F38: Média | G38: 46049 | H38: Concluída | I38: 46044 | J38: =IF(I38="","",I38-B38) -> 2 | K38: =IF(H38="Concluída",IF(I38>G38,"Sim","Não"),IF($P$2>G38,"Sim","Não")) -> Não | L38: =TEXT(B38,"mmm") -> jan | M38: Demanda simulada para portfólio
A39: ADM-036 | B39: 46117 | C39: Financeiro | D39: Solicitação de pagamento | E39: Diego Alves | F39: Média | G39: 46124 | H39: Em andamento | J39: =IF(I39="","",I39-B39) | K39: =IF(H39="Concluída",IF(I39>G39,"Sim","Não"),IF($P$2>G39,"Sim","Não")) -> Sim | L39: =TEXT(B39,"mmm") -> abr | M39: Demanda simulada para portfólio
A40: ADM-037 | B40: 46075 | C40: Operações | D40: Apoio a reunião | E40: Elisa Rocha | F40: Baixa | G40: 46087 | H40: Concluída | I40: 46088 | J40: =IF(I40="","",I40-B40) -> 13 | K40: =IF(H40="Concluída",IF(I40>G40,"Sim","Não"),IF($P$2>G40,"Sim","Não")) -> Sim | L40: =TEXT(B40,"mmm") -> fev | M40: Demanda simulada para portfólio
...

Sheet Dashboard
A1: Dashboard Administrativo — Jan a Jun/2026
A3: Indicadores de acompanhamento de solicitações administrativas | Projeto simulado
A5: Total de Solicitações | B5: =COUNTA('Base Administrativa'!A4:A63) -> 60 | D5: Concluídas | E5: =COUNTIF('Base Administrativa'!H4:H63,"Concluída") -> 38 | G5: Em Andamento | H5: =COUNTIF('Base Administrativa'!H4:H63,"Em andamento") -> 15 | J5: Pendentes | K5: =COUNTIF('Base Administrativa'!H4:H63,"Pendente") -> 7
A8: Atrasadas | B8: =COUNTIF('Base Administrativa'!K4:K63,"Sim") -> 32 | D8: Taxa de Conclusão | E8: =IFERROR(E5/B5,0) -> 0.63333333 | G8: Tempo Médio (dias) | H8: =IFERROR(SUM('Base Administrativa'!J4:J63)/COUNT('Base Administrativa'!J4:J63),0) -> 6.3684211 | J8: Alta Prioridade | K8: =COUNTIF('Base Administrativa'!F4:F63,"Alta") -> 12
A12: Solicitações por Setor | B12: Quantidade | D12: Demandas por Tipo | E12: Quantidade
A13: Financeiro | B13: =COUNTIF('Base Administrativa'!$C$4:$C$63,A13) -> 10 | D13: Compra de material | E13: =COUNTIF('Base Administrativa'!$D$4:$D$63,D13) -> 7
A14: RH | B14: =COUNTIF('Base Administrativa'!$C$4:$C$63,A14) -> 9 | D14: Atualização cadastral | E14: =COUNTIF('Base Administrativa'!$D$4:$D$63,D14) -> 6
A15: Comercial | B15: =COUNTIF('Base Administrativa'!$C$4:$C$63,A15) -> 7 | D15: Emissão de documento | E15: =COUNTIF('Base Administrativa'!$D$4:$D$63,D15) -> 8
A16: Operações | B16: =COUNTIF('Base Administrativa'!$C$4:$C$63,A16) -> 10 | D16: Organização de arquivo | E16: =COUNTIF('Base Administrativa'!$D$4:$D$63,D16) -> 9
A17: TI | B17: =COUNTIF('Base Administrativa'!$C$4:$C$63,A17) -> 11 | D17: Apoio a reunião | E17: =COUNTIF('Base Administrativa'!$D$4:$D$63,D17) -> 8
A18: Diretoria | B18: =COUNTIF('Base Administrativa'!$C$4:$C$63,A18) -> 13 | D18: Cadastro em sistema | E18: =COUNTIF('Base Administrativa'!$D$4:$D$63,D18) -> 5
D19: Relatório administrativo | E19: =COUNTIF('Base Administrativa'!$D$4:$D$63,D19) -> 8
D20: Solicitação de pagamento | E20: =COUNTIF('Base Administrativa'!$D$4:$D$63,D20) -> 9
A22: Status | B22: Quantidade | D22: Mês | E22: Solicitações
A23: Concluída | B23: =COUNTIF('Base Administrativa'!$H$4:$H$63,A23) -> 38 | D23: jan | E23: =COUNTIF('Base Administrativa'!$L$4:$L$63,D23) -> 14
A24: Em andamento | B24: =COUNTIF('Base Administrativa'!$H$4:$H$63,A24) -> 15 | D24: fev | E24: =COUNTIF('Base Administrativa'!$L$4:$L$63,D24) -> 9
A25: Pendente | B25: =COUNTIF('Base Administrativa'!$H$4:$H$63,A25) -> 7 | D25: mar | E25: =COUNTIF('Base Administrativa'!$L$4:$L$63,D25) -> 8
D26: abr | E26: =COUNTIF('Base Administrativa'!$L$4:$L$63,D26) -> 10
D27: mai | E27: =COUNTIF('Base Administrativa'!$L$4:$L$63,D27) -> 9
D28: jun | E28: =COUNTIF('Base Administrativa'!$L$4:$L$63,D28) -> 10

Sheet Power BI - Guia
A1: Como montar o Dashboard no Power BI
A3: Etapa | B3: O que fazer | C3: Campo/Medida | D3: Visual sugerido | E3: Objetivo | F3: Observação
A4: 1 | B4: Importar a tabela SolicitaçõesAdministrativas do Excel | C4: Base Administrativa | D4: Obter Dados > Excel | E4: Carregar a base | F4: Use a tabela já estruturada.
A5: 2 | B5: Criar cartões de KPI | C5: Total, Concluídas, Em andamento, Pendentes, Atrasadas | D5: Cartões | E5: Resumo executivo | F5: Repita os indicadores do Dashboard do Excel.
A6: 3 | B6: Calcular taxa de conclusão | C6: Concluídas / Total | D6: Cartão percentual | E6: Mostrar eficiência | F6: Formatar como %.
A7: 4 | B7: Analisar solicitações por setor | C7: Setor Solicitante + contagem de Protocolo | D7: Gráfico de colunas | E7: Identificar setores com maior demanda | F7: Ordenar do maior para o menor.
A8: 5 | B8: Analisar tipo de demanda | C8: Tipo de Demanda + contagem | D8: Gráfico de barras | E8: Identificar atividades mais frequentes | F8: Use rótulos de dados.
A9: 6 | B9: Analisar status | C9: Status + contagem | D9: Rosca ou barras | E9: Acompanhar andamento | F9: Concluída, Em andamento e Pendente.
A10: 7 | B10: Analisar evolução | C10: Mês + contagem de Protocolo | D10: Linha | E10: Visualizar volume ao longo do tempo | F10: Ordenar cronologicamente.
A11: 8 | B11: Adicionar filtros | C11: Setor, Responsável, Prioridade e Status | D11: Segmentações | E11: Tornar o painel interativo | F11: Permite ao recrutador explorar os dados.

Sheet Portfólio
A1: Texto para o Portfólio — Dashboard Administrativo
A3: Campo | B3: Conteúdo
A4: Título | B4: Dashboard Administrativo — Controle de Solicitações
A5: Objetivo | B5: Desenvolver uma base de controle administrativo e um painel para acompanhar solicitações, prazos, prioridades, responsáveis e status.
A6: Ferramentas | B6: Excel e Power BI
A7: Etapas | B7: Estruturação da base; padronização de categorias; criação de fórmulas; tratamento de prazos; definição de KPIs; construção do dashboard; preparação para Power BI.
A8: Competências demonstradas | B8: Organização de dados, Excel intermediário, acompanhamento de prazos, análise de indicadores, construção de dashboard e visão administrativa.
A9: Resultados | B9: Painel com indicadores de volume, conclusão, atrasos, prioridades, distribuição por setor/tipo e evolução mensal.
